{
 "cells": [
  {
   "cell_type": "code",
   "id": "initial_id",
   "metadata": {
    "collapsed": true,
    "ExecuteTime": {
     "end_time": "2024-07-11T20:55:04.407425Z",
     "start_time": "2024-07-11T20:55:04.294625Z"
    }
   },
   "source": [
    "from huggingface_hub import notebook_login\n",
    "\n",
    "notebook_login()"
   ],
   "outputs": [
    {
     "data": {
      "text/plain": [
       "VBox(children=(HTML(value='<center> <img\\nsrc=https://huggingface.co/front/assets/huggingface_logo-noborder.svâ€¦"
      ],
      "application/vnd.jupyter.widget-view+json": {
       "version_major": 2,
       "version_minor": 0,
       "model_id": "a1c494e8efef466d9b9f0bfb6a62f538"
      }
     },
     "metadata": {},
     "output_type": "display_data"
    }
   ],
   "execution_count": 1
  },
  {
   "metadata": {},
   "cell_type": "code",
   "outputs": [],
   "execution_count": null,
   "source": "",
   "id": "d0e410503fba5103"
  },
  {
   "metadata": {
    "ExecuteTime": {
     "end_time": "2024-07-11T21:07:02.975482Z",
     "start_time": "2024-07-11T21:07:02.973282Z"
    }
   },
   "cell_type": "code",
   "source": "local_model_path = \"/Users/jorgen/Documents/LHL/LLM/pythonProject/my_model\"",
   "id": "f701b243e2cd288c",
   "outputs": [],
   "execution_count": 12
  },
  {
   "metadata": {
    "ExecuteTime": {
     "end_time": "2024-07-11T21:07:04.002191Z",
     "start_time": "2024-07-11T21:07:03.899208Z"
    }
   },
   "cell_type": "code",
   "source": [
    "from transformers import DistilBertForSequenceClassification, DistilBertTokenizer, Trainer, TrainingArguments\n",
    "from huggingface_hub import HfApi, HfFolder, Repository"
   ],
   "id": "2010a3a38b4f192e",
   "outputs": [
    {
     "name": "stdout",
     "output_type": "stream",
     "text": [
      "Unexpected exception formatting exception. Falling back to standard exception\n"
     ]
    },
    {
     "name": "stderr",
     "output_type": "stream",
     "text": [
      "Traceback (most recent call last):\n",
      "  File \"/Library/anaconda3/lib/python3.11/site-packages/transformers/utils/import_utils.py\", line 1364, in _get_module\n",
      "  File \"/Library/anaconda3/lib/python3.11/importlib/__init__.py\", line 126, in import_module\n",
      "    return _bootstrap._gcd_import(name[level:], package, level)\n",
      "           ^^^^^^^^^^^^^^^^^^^^^^^^^^^^^^^^^^^^^^^^^^^^^^^^^^^^\n",
      "  File \"<frozen importlib._bootstrap>\", line 1204, in _gcd_import\n",
      "  File \"<frozen importlib._bootstrap>\", line 1176, in _find_and_load\n",
      "  File \"<frozen importlib._bootstrap>\", line 1126, in _find_and_load_unlocked\n",
      "  File \"<frozen importlib._bootstrap>\", line 241, in _call_with_frames_removed\n",
      "  File \"<frozen importlib._bootstrap>\", line 1204, in _gcd_import\n",
      "  File \"<frozen importlib._bootstrap>\", line 1176, in _find_and_load\n",
      "  File \"<frozen importlib._bootstrap>\", line 1147, in _find_and_load_unlocked\n",
      "  File \"<frozen importlib._bootstrap>\", line 690, in _load_unlocked\n",
      "  File \"<frozen importlib._bootstrap_external>\", line 940, in exec_module\n",
      "  File \"<frozen importlib._bootstrap>\", line 241, in _call_with_frames_removed\n",
      "  File \"/Library/anaconda3/lib/python3.11/site-packages/transformers/models/__init__.py\", line 15, in <module>\n",
      "    from . import (\n",
      "  File \"/Library/anaconda3/lib/python3.11/site-packages/transformers/models/depth_anything/__init__.py\", line 16, in <module>\n",
      "    from ...file_utils import _LazyModule, is_torch_available\n",
      "  File \"/Library/anaconda3/lib/python3.11/site-packages/transformers/file_utils.py\", line 26, in <module>\n",
      "    from .utils import (\n",
      "ImportError: cannot import name 'is_torch_xla_available' from 'transformers.utils' (/Library/anaconda3/lib/python3.11/site-packages/transformers/utils/__init__.py)\n",
      "\n",
      "The above exception was the direct cause of the following exception:\n",
      "\n",
      "Traceback (most recent call last):\n",
      "  File \"/Library/anaconda3/lib/python3.11/site-packages/IPython/core/interactiveshell.py\", line 3553, in run_code\n",
      "    exec(code_obj, self.user_global_ns, self.user_ns)\n",
      "  File \"/var/folders/s_/9471r3s113g9rt1cmsvmp2lw0000gn/T/ipykernel_85265/4091331172.py\", line 1, in <module>\n",
      "    from transformers import DistilBertForSequenceClassification, DistilBertTokenizer, Trainer, TrainingArguments\n",
      "  File \"<frozen importlib._bootstrap>\", line 1229, in _handle_fromlist\n",
      "  File \"/Library/anaconda3/lib/python3.11/site-packages/transformers/utils/import_utils.py\", line 1354, in __getattr__\n",
      "    {0} requires the PIL library but it was not found in your environment. You can install it with pip:\n",
      "                         ^^^^^^^^^^^^^^^^^^^^^^^^^^^^^^^^^^^^^^^^^^^^^\n",
      "  File \"/Library/anaconda3/lib/python3.11/site-packages/transformers/utils/import_utils.py\", line 1366, in _get_module\n",
      "    PYCTCDECODE_IMPORT_ERROR = \"\"\"\n",
      "                ^^^^^^^^^^^^^^^^^^\n",
      "RuntimeError: Failed to import transformers.models.distilbert because of the following error (look up to see its traceback):\n",
      "cannot import name 'is_torch_xla_available' from 'transformers.utils' (/Library/anaconda3/lib/python3.11/site-packages/transformers/utils/__init__.py)\n",
      "\n",
      "During handling of the above exception, another exception occurred:\n",
      "\n",
      "Traceback (most recent call last):\n",
      "  File \"/Library/anaconda3/lib/python3.11/site-packages/IPython/core/interactiveshell.py\", line 2144, in showtraceback\n",
      "    stb = self.InteractiveTB.structured_traceback(\n",
      "          ^^^^^^^^^^^^^^^^^^^^^^^^^^^^^^^^^^^^^^^^\n",
      "  File \"/Library/anaconda3/lib/python3.11/site-packages/IPython/core/ultratb.py\", line 1435, in structured_traceback\n",
      "    return FormattedTB.structured_traceback(\n",
      "           ^^^^^^^^^^^^^^^^^^^^^^^^^^^^^^^^^\n",
      "  File \"/Library/anaconda3/lib/python3.11/site-packages/IPython/core/ultratb.py\", line 1326, in structured_traceback\n",
      "    return VerboseTB.structured_traceback(\n",
      "           ^^^^^^^^^^^^^^^^^^^^^^^^^^^^^^^\n",
      "  File \"/Library/anaconda3/lib/python3.11/site-packages/IPython/core/ultratb.py\", line 1192, in structured_traceback\n",
      "    formatted_exceptions += self.format_exception_as_a_whole(etype, evalue, etb, lines_of_context,\n",
      "                            ^^^^^^^^^^^^^^^^^^^^^^^^^^^^^^^^^^^^^^^^^^^^^^^^^^^^^^^^^^^^^^^^^^^^^^\n",
      "  File \"/Library/anaconda3/lib/python3.11/site-packages/IPython/core/ultratb.py\", line 1088, in format_exception_as_a_whole\n",
      "    frames.append(self.format_record(record))\n",
      "                  ^^^^^^^^^^^^^^^^^^^^^^^^^^\n",
      "  File \"/Library/anaconda3/lib/python3.11/site-packages/IPython/core/ultratb.py\", line 970, in format_record\n",
      "    frame_info.lines, Colors, self.has_colors, lvals\n",
      "    ^^^^^^^^^^^^^^^^\n",
      "  File \"/Library/anaconda3/lib/python3.11/site-packages/IPython/core/ultratb.py\", line 792, in lines\n",
      "    return self._sd.lines\n",
      "           ^^^^^^^^^^^^^^\n",
      "  File \"/Library/anaconda3/lib/python3.11/site-packages/stack_data/utils.py\", line 145, in cached_property_wrapper\n",
      "    value = obj.__dict__[self.func.__name__] = self.func(obj)\n",
      "                                               ^^^^^^^^^^^^^^\n",
      "  File \"/Library/anaconda3/lib/python3.11/site-packages/stack_data/core.py\", line 698, in lines\n",
      "    pieces = self.included_pieces\n",
      "             ^^^^^^^^^^^^^^^^^^^^\n",
      "  File \"/Library/anaconda3/lib/python3.11/site-packages/stack_data/utils.py\", line 145, in cached_property_wrapper\n",
      "    value = obj.__dict__[self.func.__name__] = self.func(obj)\n",
      "                                               ^^^^^^^^^^^^^^\n",
      "  File \"/Library/anaconda3/lib/python3.11/site-packages/stack_data/core.py\", line 649, in included_pieces\n",
      "    pos = scope_pieces.index(self.executing_piece)\n",
      "                             ^^^^^^^^^^^^^^^^^^^^\n",
      "  File \"/Library/anaconda3/lib/python3.11/site-packages/stack_data/utils.py\", line 145, in cached_property_wrapper\n",
      "    value = obj.__dict__[self.func.__name__] = self.func(obj)\n",
      "                                               ^^^^^^^^^^^^^^\n",
      "  File \"/Library/anaconda3/lib/python3.11/site-packages/stack_data/core.py\", line 628, in executing_piece\n",
      "    return only(\n",
      "           ^^^^^\n",
      "  File \"/Library/anaconda3/lib/python3.11/site-packages/executing/executing.py\", line 164, in only\n",
      "    raise NotOneValueFound('Expected one value, found 0')\n",
      "executing.executing.NotOneValueFound: Expected one value, found 0\n"
     ]
    }
   ],
   "execution_count": 13
  },
  {
   "metadata": {},
   "cell_type": "code",
   "outputs": [],
   "execution_count": null,
   "source": "",
   "id": "2570495962da760"
  }
 ],
 "metadata": {
  "kernelspec": {
   "display_name": "Python 3",
   "language": "python",
   "name": "python3"
  },
  "language_info": {
   "codemirror_mode": {
    "name": "ipython",
    "version": 2
   },
   "file_extension": ".py",
   "mimetype": "text/x-python",
   "name": "python",
   "nbconvert_exporter": "python",
   "pygments_lexer": "ipython2",
   "version": "2.7.6"
  }
 },
 "nbformat": 4,
 "nbformat_minor": 5
}
